Traceback (most recent call last):
  File "C:\Users\Susan Notess\AppData\Local\Packages\PythonSoftwareFoundation.Python.3.9_qbz5n2kfra8p0\LocalCache\local-packages\Python39\site-packages\jupyter_cache\executors\utils.py", line 51, in single_nb_execution
    executenb(
  File "C:\Users\Susan Notess\AppData\Local\Packages\PythonSoftwareFoundation.Python.3.9_qbz5n2kfra8p0\LocalCache\local-packages\Python39\site-packages\nbclient\client.py", line 1204, in execute
    return NotebookClient(nb=nb, resources=resources, km=km, **kwargs).execute()
  File "C:\Users\Susan Notess\AppData\Local\Packages\PythonSoftwareFoundation.Python.3.9_qbz5n2kfra8p0\LocalCache\local-packages\Python39\site-packages\nbclient\util.py", line 84, in wrapped
    return just_run(coro(*args, **kwargs))
  File "C:\Users\Susan Notess\AppData\Local\Packages\PythonSoftwareFoundation.Python.3.9_qbz5n2kfra8p0\LocalCache\local-packages\Python39\site-packages\nbclient\util.py", line 62, in just_run
    return loop.run_until_complete(coro)
  File "C:\Program Files\WindowsApps\PythonSoftwareFoundation.Python.3.9_3.9.3568.0_x64__qbz5n2kfra8p0\lib\asyncio\base_events.py", line 647, in run_until_complete
    return future.result()
  File "C:\Users\Susan Notess\AppData\Local\Packages\PythonSoftwareFoundation.Python.3.9_qbz5n2kfra8p0\LocalCache\local-packages\Python39\site-packages\nbclient\client.py", line 663, in async_execute
    await self.async_execute_cell(
  File "C:\Users\Susan Notess\AppData\Local\Packages\PythonSoftwareFoundation.Python.3.9_qbz5n2kfra8p0\LocalCache\local-packages\Python39\site-packages\nbclient\client.py", line 965, in async_execute_cell
    await self._check_raise_for_error(cell, cell_index, exec_reply)
  File "C:\Users\Susan Notess\AppData\Local\Packages\PythonSoftwareFoundation.Python.3.9_qbz5n2kfra8p0\LocalCache\local-packages\Python39\site-packages\nbclient\client.py", line 862, in _check_raise_for_error
    raise CellExecutionError.from_cell_and_msg(cell, exec_reply_content)
nbclient.exceptions.CellExecutionError: An error occurred while executing the following cell:
------------------
# before tweeting, we recommend you display the output first:

display("This is tweet was posted by a computer program!")


# this is the basic structure to post a tweet. if you want, try running this code block and
# check your twitter account to see if it worked!

client.create_tweet(text="This is tweet was posted by a computer program!")
------------------

[1;31m---------------------------------------------------------------------------[0m
[1;31mNameError[0m                                 Traceback (most recent call last)
Input [1;32mIn [3][0m, in [0;36m<cell line: 9>[1;34m()[0m
[0;32m      3[0m display([38;5;124m"[39m[38;5;124mThis is tweet was posted by a computer program![39m[38;5;124m"[39m)
[0;32m      6[0m [38;5;66;03m# this is the basic structure to post a tweet. if you want, try running this code block and[39;00m
[0;32m      7[0m [38;5;66;03m# check your twitter account to see if it worked![39;00m
[1;32m----> 9[0m [43mclient[49m[38;5;241m.[39mcreate_tweet(text[38;5;241m=[39m[38;5;124m"[39m[38;5;124mThis is tweet was posted by a computer program![39m[38;5;124m"[39m)

[1;31mNameError[0m: name 'client' is not defined
NameError: name 'client' is not defined

